Workbook

Sheet Lisez-moi
A1: Univers Barça — Plan de réalisation et suivi du projet
A2: Fichier de pilotage : planning par jalons, Gantt, backlog complet et tableau de bord. Généré à partir du backlog des 3 dépôts GitHub.
A4: Comment l’utiliser
A5: 1. « Paramètres » : date de début, nombre de développeurs par flux, facteur de focus, marge. Tout le planning se recalcule.
A6: 2. « Étapes » : plan de réalisation étape par étape (phases 0 à 3), avec charge, dates et critères de sortie.
A7: 3. « Jalons » : jalons de fin de phase (dates calculées, date réelle à saisir) ; « Gantt » : barres par semaine et par épopée.
A8: 4. « Épopées » : plan détaillé par épopée (flux × phase) avec avancement ; « Backlog » : une ligne par issue avec statut à mettre à jour.
A9: 5. « Suivi » : tableau de bord (avancement par phase, par flux, par statut) ; « Scénarios » : durée selon la taille de l’équipe ; « Décisions et risques ».
A10: Code couleur
A11: Texte bleu sur fond jaune = cellule à modifier · texte noir = formule (ne pas écraser) · couleurs de phase : gris-bleu (0), grenat (1), bleu (2), or (3).
A12: Hypothèses (à valider)
A13: • Charge par taille d’issue (XS 0,25 j · S 0,5 · M 1 · L 2 · XL 3,5) : estimation indicative à recalibrer après les premiers sprints (feuille Paramètres).
... A18: Mettre à jour la colonne « Statut » (et, si utile, « Début réel » / « Fin réel ») dans « Backlog » : « Épopées », « Gantt », « Jalons » et « Suivi » se recalculent seuls.

Sheet Paramètres
A1: Paramètres du planning
A2: Cellules en bleu sur fond jaune = à modifier ; tout le planning (durées, dates, Gantt, jalons) se recalcule.
A4: Date de début du projet | B4: 46328 | C4: Lundi conseillé. Hypothèse : début après cadrage (secrets, VPS, Firebase, décisions).
A5: Facteur de focus (productivité réelle) | B5: 0.8 | C5: Réunions, revues, aléas : 80 % du temps nominal est productif.
A6: Marge pour aléas | B6: 0.15 | C6: Ajoutée à la charge de chaque épopée.
A7: Développeurs sur le flux API | B7: 3 | C7: Équivalents temps plein (peut être décimal : 1,5).
A8: Développeurs sur le flux Mobile | B8: 3
A9: Développeurs sur le flux Admin | B9: 2
A10: Décalage Mobile/Admin sur l’API (jours ouvrés) | B10: 20 | C10: En phases 1 à 3, Mobile/Admin démarrent N jours ouvrés après l’API (endpoints disponibles).
A11: Durée de recette par phase (jours ouvrés) | B11: 10 | C11: UAT + correctifs + observation staging (CDC §15).
A13: Barème de charge par taille (jours·personne)
A14: Taille | B14: Charge (j) | C14: Signification
A15: XS | B15: 0.25 | C15: ≈ 2 h : détail, libellé, petit test
A16: S | B16: 0.5 | C16: ≈ demi-journée
A17: M | B17: 1 | C17: ≈ 1 jour
A18: L | B18: 2 | C18: ≈ 2 jours (à redécouper si possible)
A19: XL | B19: 3.5 | C19: ≈ 3-4 jours (à redécouper)
A22: Phases
A23: Phase | B23: Intitulé | C23: Objectif de sortie (CDC §5.5)
A24: 0 | B24: Phase 0 — Socle technique | C24: Environnements opérationnels, premier commit déployé en staging
A25: 1 | B25: Phase 1 — MVP | C25: Version testable par un cercle restreint d’utilisateurs
A26: 2 | B26: Phase 2 — Communautaire & compétitif | C26: Version communautaire complète
A27: 3 | B27: Phase 3 — Fonctionnalités avancées | C27: Version complète du périmètre fonctionnel cible

Sheet Étapes
A1: Plan de réalisation — étapes détaillées
A2: Chaque étape regroupe des épopées du backlog ; charge, début et fin sont calculés depuis « Épopées ». Les étapes « Recette » ont une durée fixe (Paramètres).
A5: Étape | B5: Phase | C5: Intitulé | D5: Objectif | E5: Épopées (backlog) | F5: Prérequis | G5: Livrables | H5: Critères de sortie | I5: Charge (j) | J5: Début | K5: Fin | L5: Durée (jo) | M5: Statut
A6: 0.1 | B6: 0 | C6: Cadrage et mise en place (avant J0) | D6: Débloquer l’environnement de travail avant le premier jour de développement. | E6: Aucune (actions manuelles) | F6: — | G6: Secrets GitHub (VPS, Firebase, stores), environnements staging/production, projet GitHub relié, protection des branches, nom de domaine et DNS. | H6: Décisions « à confirmer » tranchées (voir feuille Décisions) ; pipelines CD capables de déployer. | I6: 0 | J6: =WORKDAY(Paramètres!$B$4,-10) -> 46314 | K6: =WORKDAY(Paramètres!$B$4,-1) -> 46325 | L6: =NETWORKDAYS(J6,K6) -> 10 | M6: À faire
A7: 0.2 | B7: 0 | C7: Socle API et plateforme | D7: Rendre l’API exploitable : configuration, observabilité, sécurité de base, identité. | E7: API-PLAT, API-AUTH | F7: 0.1 | G7: API en staging avec /health, /metrics, Swagger, migrations, jobs de base. | H7: CI verte ; staging déployé ; tests de charge « smoke » passants. | I7: =SUMIFS(Épopées!$G$6:$G$59,Épopées!$A$6:$A$59,"API-PLAT|0")+SUMIFS(Épopées!$G$6:$G$59,Épopées!$A$6:$A$59,"API-AUTH|0") -> 8.75 | J7: =MIN(SUMIFS(Épopées!$L$6:$L$59,Épopées!$A$6:$A$59,"API-PLAT|0"),SUMIFS(Épopées!$L$6:$L$59,Épopées!$A$6:$A$59,"API-AUTH|0")) -> 46328 | K7: =MAX(SUMIFS(Épopées!$M$6:$M$59,Épopées!$A$6:$A$59,"API-PLAT|0"),SUMIFS(Épopées!$M$6:$M$59,Épopées!$A$6:$A$59,"API-AUTH|0")) -> 46332 | L7: =NETWORKDAYS(J7,K7) -> 5 | M7: À faire
A8: 0.3 | B8: 0 | C8: Design system mobile | D8: Implémenter tokens, composants et animations du design system Flutter. | E8: MOB-ZA, MOB-ZB, MOB-ZC, MOB-ZD, MOB-ZE | F8: 0.1 | G8: Widgets sous lib/core/widgets, thèmes clair/sombre, golden tests. | H8: Planches ZA-ZE reproduites à l’identique ; goldens verts. | I8: =SUMIFS(Épopées!$G$6:$G$59,Épopées!$A$6:$A$59,"MOB-ZA|0")+SUMIFS(Épopées!$G$6:$G$59,Épopées!$A$6:$A$59,"MOB-ZB|0")+SUMIFS(Épopées!$G$6:$G$59,Épopées!$A$6:$A$59,"MOB-ZC|0")+SUMIFS(Épopées!$G$6:$G$59,Épopées!$A$6:$A$59,"MOB-ZD|0")+SUMIFS(Épopées!$G$6:$G$59,Épopées!$A$6:$A$59,"MOB-ZE|0") -> 89.5 | J8: =MIN(SUMIFS(Épopées!$L$6:$L$59,Épopées!$A$6:$A$59,"MOB-ZA|0"),SUMIFS(Épopées!$L$6:$L$59,Épopées!$A$6:$A$59,"MOB-ZB|0"),SUMIFS(Épopées!$L$6:$L$59,Épopées!$A$6:$A$59,"MOB-ZC|0"),SUMIFS(Épopées!$L$6:$L$59,Épopées!$A$6:$A$59,"MOB-ZD|0"),SUMIFS(Épopées!$L$6:$L$59,Épopées!$A$6:$A$59,"MOB-ZE|0")) -> 46363 | K8: =MAX(SUMIFS(Épopées!$M$6:$M$59,Épopées!$A$6:$A$59,"MOB-ZA|0"),SUMIFS(Épopées!$M$6:$M$59,Épopées!$A$6:$A$59,"MOB-ZB|0"),SUMIFS(Épopées!$M$6:$M$59,Épopées!$A$6:$A$59,"MOB-ZC|0"),SUMIFS(Épopées!$M$6:$M$59,Épopées!$A$6:$A$59,"MOB-ZD|0"),SUMIFS(Épopées!$M$6:$M$59,Épopées!$A$6:$A$59,"MOB-ZE|0")) -> 46423 | L8: =NETWORKDAYS(J8,K8) -> 45 | M8: À faire
A9: 0.4 | B9: 0 | C9: Socle Flutter et états système | D9: Navigation, réseau, stockage, i18n, Firebase, écrans système. | E9: MOB-FND, MOB-A | F9: 0.3 (en parallèle) | G9: ShellRoute 5 onglets, AuthBloc, Chopper + refresh, Drift, ARB FR/EN/ES, écrans A-01…A-10. | H9: App installable (APK/IPA) sur staging ; états offline/5xx/429/maintenance gérés. | I9: =SUMIFS(Épopées!$G$6:$G$59,Épopées!$A$6:$A$59,"MOB-FND|0")+SUMIFS(Épopées!$G$6:$G$59,Épopées!$A$6:$A$59,"MOB-A|0") -> 66.25 | J9: =MIN(SUMIFS(Épopées!$L$6:$L$59,Épopées!$A$6:$A$59,"MOB-FND|0"),SUMIFS(Épopées!$L$6:$L$59,Épopées!$A$6:$A$59,"MOB-A|0")) -> 46328 | K9: =MAX(SUMIFS(Épopées!$M$6:$M$59,Épopées!$A$6:$A$59,"MOB-FND|0"),SUMIFS(Épopées!$M$6:$M$59,Épopées!$A$6:$A$59,"MOB-A|0")) -> 46435 | L9: =NETWORKDAYS(J9,K9) -> 78 | M9: À faire
A10: 0.5 | B10: 0 | C10: Socle et design system admin | D10: Base du back-office : routage par rôle, composants, qualité. | E10: ADM-FND, ADM-ADS | F10: 0.1 | G10: Composants shadcn-style, layout responsive, tests Vitest/Playwright. | H10: Admin déployé en staging ; accessibilité de base validée. | I10: =SUMIFS(Épopées!$G$6:$G$59,Épopées!$A$6:$A$59,"ADM-FND|0")+SUMIFS(Épopées!$G$6:$G$59,Épopées!$A$6:$A$59,"ADM-ADS|0") -> 60 | J10: =MIN(SUMIFS(Épopées!$L$6:$L$59,Épopées!$A$6:$A$59,"ADM-FND|0"),SUMIFS(Épopées!$L$6:$L$59,Épopées!$A$6:$A$59,"ADM-ADS|0")) -> 46328 | K10: =MAX(SUMIFS(Épopées!$M$6:$M$59,Épopées!$A$6:$A$59,"ADM-FND|0"),SUMIFS(Épopées!$M$6:$M$59,Épopées!$A$6:$A$59,"ADM-ADS|0")) -> 46387 | L10: =NETWORKDAYS(J10,K10) -> 44 | M10: À faire
A11: 1.1 | B11: 1 | C11: Identité, comptes et paramètres | D11: Inscription, connexion, RGPD, profil et paramètres côté API, mobile et admin. | E11: API-AUTH, MOB-B, MOB-Q, ADM-WA, ADM-WI | F11: 0.2, 0.4, 0.5 | G11: Parcours onboarding → compte vérifié ; export/suppression RGPD ; comptes admin + 2FA. | H11: Parcours d’inscription E2E vert ; consentements historisés ; tests de sécurité auth verts. | I11: =SUMIFS(Épopées!$G$6:$G$59,Épopées!$A$6:$A$59,"API-AUTH|1")+SUMIFS(Épopées!$G$6:$G$59,Épopées!$A$6:$A$59,"MOB-B|1")+SUMIFS(Épopées!$G$6:$G$59,Épopées!$A$6:$A$59,"MOB-Q|1")+SUMIFS(Épopées!$G$6:$G$59,Épopées!$A$6:$A$59,"ADM-WA|1")+SUMIFS(Épopées!$G$6:$G$59,Épopées!$A$6:$A$59,"ADM-WI|1") -> 146.75 | J11: =MIN(SUMIFS(Épopées!$L$6:$L$59,Épopées!$A$6:$A$59,"API-AUTH|1"),SUMIFS(Épopées!$L$6:$L$59,Épopées!$A$6:$A$59,"MOB-B|1"),SUMIFS(Épopées!$L$6:$L$59,Épopées!$A$6:$A$59,"MOB-Q|1"),SUMIFS(Épopées!$L$6:$L$59,Épopées!$A$6:$A$59,"ADM-WA|1"),SUMIFS(Épopées!$L$6:$L$59,Épopées!$A$6:$A$59,"ADM-WI|1")) -> 46364 | K11: =MAX(SUMIFS(Épopées!$M$6:$M$59,Épopées!$A$6:$A$59,"API-AUTH|1"),SUMIFS(Épopées!$M$6:$M$59,Épopées!$A$6:$A$59,"MOB-B|1"),SUMIFS(Épopées!$M$6:$M$59,Épopées!$A$6:$A$59,"MOB-Q|1"),SUMIFS(Épopées!$M$6:$M$59,Épopées!$A$6:$A$59,"ADM-WA|1"),SUMIFS(Épopées!$M$6:$M$59,Épopées!$A$6:$A$59,"ADM-WI|1")) -> 46563 | L11: =NETWORKDAYS(J11,K11) -> 144 | M11: À faire
A12: 1.2 | B12: 1 | C12: Données football, historique et contenu | D12: Alimenter et publier les données joueurs/matchs ; consultation côté mobile. | E12: API-FOOT, MOB-F, ADM-WC, ADM-WD, ADM-WE | F12: 1.1 (auth) | G12: Synchro API football, CRUD joueurs/matchs/anecdotes, historique et fiches mobiles. | H12: Données réelles visibles dans l’app ; workflow de publication et traductions opérationnel. | I12: =SUMIFS(Épopées!$G$6:$G$59,Épopées!$A$6:$A$59,"API-FOOT|1")+SUMIFS(Épopées!$G$6:$G$59,Épopées!$A$6:$A$59,"MOB-F|1")+SUMIFS(Épopées!$G$6:$G$59,Épopées!$A$6:$A$59,"ADM-WC|1")+SUMIFS(Épopées!$G$6:$G$59,Épopées!$A$6:$A$59,"ADM-WD|1")+SUMIFS(Épopées!$G$6:$G$59,Épopées!$A$6:$A$59,"ADM-WE|1") -> 159.5 | J12: =MIN(SUMIFS(Épopées!$L$6:$L$59,Épopées!$A$6:$A$59,"API-FOOT|1"),SUMIFS(Épopées!$L$6:$L$59,Épopées!$A$6:$A$59,"MOB-F|1"),SUMIFS(Épopées!$L$6:$L$59,Épopées!$A$6:$A$59,"ADM-WC|1"),SUMIFS(Épopées!$L$6:$L$59,Épopées!$A$6:$A$59,"ADM-WD|1"),SUMIFS(Épopées!$L$6:$L$59,Épopées!$A$6:$A$59,"ADM-WE|1")) -> 46399 | K12: =MAX(SUMIFS(Épopées!$M$6:$M$59,Épopées!$A$6:$A$59,"API-FOOT|1"),SUMIFS(Épopées!$M$6:$M$59,Épopées!$A$6:$A$59,"MOB-F|1"),SUMIFS(Épopées!$M$6:$M$59,Épopées!$A$6:$A$59,"ADM-WC|1"),SUMIFS(Épopées!$M$6:$M$59,Épopées!$A$6:$A$59,"ADM-WD|1"),SUMIFS(Épopées!$M$6:$M$59,Épopées!$A$6:$A$59,"ADM-WE|1")) -> 46510 | L12: =NETWORKDAYS(J12,K12) -> 80 | M12: À faire
A13: 1.3 | B13: 1 | C13: Accueil, calendrier et tableau de bord | D13: Dashboard d’accueil, calendrier et export agenda, KPI admin. | E13: API-CAL, MOB-C, MOB-L, ADM-WB | F13: 1.2 | G13: Dashboard, calendrier, export ICS / abonnement, KPI admin et recherche globale. | H13: Export ICS validé sur iOS/Android ; recherche admin < 300 ms. | I13: =SUMIFS(Épopées!$G$6:$G$59,Épopées!$A$6:$A$59,"API-CAL|1")+SUMIFS(Épopées!$G$6:$G$59,Épopées!$A$6:$A$59,"MOB-C|1")+SUMIFS(Épopées!$G$6:$G$59,Épopées!$A$6:$A$59,"MOB-L|1")+SUMIFS(Épopées!$G$6:$G$59,Épopées!$A$6:$A$59,"ADM-WB|1") -> 94 | J13: =MIN(SUMIFS(Épopées!$L$6:$L$59,Épopées!$A$6:$A$59,"API-CAL|1"),SUMIFS(Épopées!$L$6:$L$59,Épopées!$A$6:$A$59,"MOB-C|1"),SUMIFS(Épopées!$L$6:$L$59,Épopées!$A$6:$A$59,"MOB-L|1"),SUMIFS(Épopées!$L$6:$L$59,Épopées!$A$6:$A$59,"ADM-WB|1")) -> 46407 | K13: =MAX(SUMIFS(Épopées!$M$6:$M$59,Épopées!$A$6:$A$59,"API-CAL|1"),SUMIFS(Épopées!$M$6:$M$59,Épopées!$A$6:$A$59,"MOB-C|1"),SUMIFS(Épopées!$M$6:$M$59,Épopées!$A$6:$A$59,"MOB-L|1"),SUMIFS(Épopées!$M$6:$M$59,Épopées!$A$6:$A$59,"ADM-WB|1")) -> 46533 | L13: =NETWORKDAYS(J13,K13) -> 91 | M13: À faire
A14: 1.4 | B14: 1 | C14: Jeux quotidiens | D14: Guess the Player et Quiz adaptatif, classements, streaks. | E14: API-JEUX, MOB-D, MOB-E, ADM-WF | F14: 1.2 | G14: Défi quotidien, quiz adaptatif, scoring, streaks, back-office des questions. | H14: Défi identique pour tous ; anti-triche testé ; test de charge « défi du soir ». | I14: =SUMIFS(Épopées!$G$6:$G$59,Épopées!$A$6:$A$59,"API-JEUX|1")+SUMIFS(Épopées!$G$6:$G$59,Épopées!$A$6:$A$59,"MOB-D|1")+SUMIFS(Épopées!$G$6:$G$59,Épopées!$A$6:$A$59,"MOB-E|1")+SUMIFS(Épopées!$G$6:$G$59,Épopées!$A$6:$A$59,"ADM-WF|1") -> 127 | J14: =MIN(SUMIFS(Épopées!$L$6:$L$59,Épopées!$A$6:$A$59,"API-JEUX|1"),SUMIFS(Épopées!$L$6:$L$59,Épopées!$A$6:$A$59,"MOB-D|1"),SUMIFS(Épopées!$L$6:$L$59,Épopées!$A$6:$A$59,"MOB-E|1"),SUMIFS(Épopées!$L$6:$L$59,Épopées!$A$6:$A$59,"ADM-WF|1")) -> 46454 | K14: =MAX(SUMIFS(Épopées!$M$6:$M$59,Épopées!$A$6:$A$59,"API-JEUX|1"),SUMIFS(Épopées!$M$6:$M$59,Épopées!$A$6:$A$59,"MOB-D|1"),SUMIFS(Épopées!$M$6:$M$59,Épopées!$A$6:$A$59,"MOB-E|1"),SUMIFS(Épopées!$M$6:$M$59,Épopées!$A$6:$A$59,"ADM-WF|1")) -> 46573 | L14: =NETWORKDAYS(J14,K14) -> 86 | M14: À faire
A15: 1.5 | B15: 1 | C15: Assistant IA Barça AI | D15: Assistant conversationnel borné aux faits, avec garde-fous et quotas. | E15: API-IA, MOB-N | F15: 1.2 | G15: Chat en streaming, historique, quotas, modération, kill switch. | H15: Jeu de tests de non-régression de prompts vert ; coûts suivis. | I15: =SUMIFS(Épopées!$G$6:$G$59,Épopées!$A$6:$A$59,"API-IA|1")+SUMIFS(Épopées!$G$6:$G$59,Épopées!$A$6:$A$59,"MOB-N|1") -> 66 | J15: =MIN(SUMIFS(Épopées!$L$6:$L$59,Épopées!$A$6:$A$59,"API-IA|1"),SUMIFS(Épopées!$L$6:$L$59,Épopées!$A$6:$A$59,"MOB-N|1")) -> 46506 | K15: =MAX(SUMIFS(Épopées!$M$6:$M$59,Épopées!$A$6:$A$59,"API-IA|1"),SUMIFS(Épopées!$M$6:$M$59,Épopées!$A$6:$A$59,"MOB-N|1")) -> 46597 | L15: =NETWORKDAYS(J15,K15) -> 66 | M15: À faire
A16: 1.6 | B16: 1 | C16: Notifications | D16: Notifications push et centre de notifications. | E16: API-NOTIF, MOB-O | F16: 1.1 | G16: Jetons d’appareil, préférences, envoi FCM, campagnes admin. | H16: Notification reçue sur iOS et Android en staging ; DLQ supervisée. | I16: =SUMIFS(Épopées!$G$6:$G$59,Épopées!$A$6:$A$59,"API-NOTIF|1")+SUMIFS(Épopées!$G$6:$G$59,Épopées!$A$6:$A$59,"MOB-O|1") -> 54.75 | J16: =MIN(SUMIFS(Épopées!$L$6:$L$59,Épopées!$A$6:$A$59,"API-NOTIF|1"),SUMIFS(Épopées!$L$6:$L$59,Épopées!$A$6:$A$59,"MOB-O|1")) -> 46485 | K16: =MAX(SUMIFS(Épopées!$M$6:$M$59,Épopées!$A$6:$A$59,"API-NOTIF|1"),SUMIFS(Épopées!$M$6:$M$59,Épopées!$A$6:$A$59,"MOB-O|1")) -> 46615 | L16: =NETWORKDAYS(J16,K16) -> 93 | M16: À faire
A17: 1.7 | B17: 1 | C17: Exploitation et supervision MVP | D17: Industrialiser : monitoring, sauvegardes, charge, supervision admin. | E17: API-PLAT, ADM-WH, ADM-WJ | F17: 1.1 à 1.6 (en continu) | G17: Dashboards Grafana, alertes, sauvegardes testées, supervision technique admin, capacité mesurée. | H17: Restauration testée ; dimensionnement serveur documenté (tests de charge). | I17: =SUMIFS(Épopées!$G$6:$G$59,Épopées!$A$6:$A$59,"API-PLAT|1")+SUMIFS(Épopées!$G$6:$G$59,Épopées!$A$6:$A$59,"ADM-WH|1")+SUMIFS(Épopées!$G$6:$G$59,Épopées!$A$6:$A$59,"ADM-WJ|1") -> 66.5 | J17: =MIN(SUMIFS(Épopées!$L$6:$L$59,Épopées!$A$6:$A$59,"API-PLAT|1"),SUMIFS(Épopées!$L$6:$L$59,Épopées!$A$6:$A$59,"ADM-WH|1"),SUMIFS(Épopées!$L$6:$L$59,Épopées!$A$6:$A$59,"ADM-WJ|1")) -> 46335 | K17: =MAX(SUMIFS(Épopées!$M$6:$M$59,Épopées!$A$6:$A$59,"API-PLAT|1"),SUMIFS(Épopées!$M$6:$M$59,Épopées!$A$6:$A$59,"ADM-WH|1"),SUMIFS(Épopées!$M$6:$M$59,Épopées!$A$6:$A$59,"ADM-WJ|1")) -> 46573 | L17: =NETWORKDAYS(J17,K17) -> 171 | M17: À faire
A18: 1.8 | B18: 1 | C18: Recette MVP et bêta fermée | D18: Valider le MVP avec un cercle restreint. | E18: Aucune épopée — durée fixe (Paramètres) | F18: 1.1 à 1.7 | G18: Rapport de recette, correctifs, version bêta (TestFlight / Firebase App Distribution). | H18: Critères de sortie du CDC §15.2 atteints (couverture, anomalies, doc, observation 48 h). | I18: 0 | J18: =WORKDAY(MAX(K11,K12,K13,K14,K15,K16,K17),1) -> 46616 | K18: =WORKDAY(J18,Paramètres!$B$11-1) -> 46629 | L18: =NETWORKDAYS(J18,K18) -> 10 | M18: À faire
A19: 2.1 | B19: 2 | C19: Communauté : carte, groupes et modération | D19: Carte communautaire, groupes locaux, modération (côté API, mobile, admin). | E19: API-COMM, API-MODER, MOB-J, MOB-K, ADM-WG, ADM-WJ | F19: Phase 1 | G19: Carte agrégée, groupes, signalements, sanctions, journal d’audit. | H19: Revue RGPD géolocalisation ; test de modération de bout en bout. | I19: =SUMIFS(Épopées!$G$6:$G$59,Épopées!$A$6:$A$59,"API-COMM|2")+SUMIFS(Épopées!$G$6:$G$59,Épopées!$A$6:$A$59,"API-MODER|2")+SUMIFS(Épopées!$G$6:$G$59,Épopées!$A$6:$A$59,"MOB-J|2")+SUMIFS(Épopées!$G$6:$G$59,Épopées!$A$6:$A$59,"MOB-K|2")+SUMIFS(Épopées!$G$6:$G$59,Épopées!$A$6:$A$59,"ADM-WG|2")+SUMIFS(Épopées!$G$6:$G$59,Épopées!$A$6:$A$59,"ADM-WJ|2") -> 168.5 | J19: =MIN(SUMIFS(Épopées!$L$6:$L$59,Épopées!$A$6:$A$59,"API-COMM|2"),SUMIFS(Épopées!$L$6:$L$59,Épopées!$A$6:$A$59,"API-MODER|2"),SUMIFS(Épopées!$L$6:$L$59,Épopées!$A$6:$A$59,"MOB-J|2"),SUMIFS(Épopées!$L$6:$L$59,Épopées!$A$6:$A$59,"MOB-K|2"),SUMIFS(Épopées!$L$6:$L$59,Épopées!$A$6:$A$59,"ADM-WG|2"),SUMIFS(Épopées!$L$6:$L$59,Épopées!$A$6:$A$59,"ADM-WJ|2")) -> 46527 | K19: =MAX(SUMIFS(Épopées!$M$6:$M$59,Épopées!$A$6:$A$59,"API-COMM|2"),SUMIFS(Épopées!$M$6:$M$59,Épopées!$A$6:$A$59,"API-MODER|2"),SUMIFS(Épopées!$M$6:$M$59,Épopées!$A$6:$A$59,"MOB-J|2"),SUMIFS(Épopées!$M$6:$M$59,Épopées!$A$6:$A$59,"MOB-K|2"),SUMIFS(Épopées!$M$6:$M$59,Épopées!$A$6:$A$59,"ADM-WG|2"),SUMIFS(Épopées!$M$6:$M$59,Épopées!$A$6:$A$59,"ADM-WJ|2")) -> 46695 | L19: =NETWORKDAYS(J19,K19) -> 121 | M19: À faire
A20: 2.2 | B20: 2 | C20: Comparateur GOAT | D20: Comparateur et votes. | E20: API-GOAT, MOB-G | F20: Phase 1 | G20: Comparateur, votes, agrégats. | H20: Anti-abus testé. | I20: =SUMIFS(Épopées!$G$6:$G$59,Épopées!$A$6:$A$59,"API-GOAT|2")+SUMIFS(Épopées!$G$6:$G$59,Épopées!$A$6:$A$59,"MOB-G|2") -> 43 | J20: =MIN(SUMIFS(Épopées!$L$6:$L$59,Épopées!$A$6:$A$59,"API-GOAT|2"),SUMIFS(Épopées!$L$6:$L$59,Épopées!$A$6:$A$59,"MOB-G|2")) -> 46580 | K20: =MAX(SUMIFS(Épopées!$M$6:$M$59,Épopées!$A$6:$A$59,"API-GOAT|2"),SUMIFS(Épopées!$M$6:$M$59,Épopées!$A$6:$A$59,"MOB-G|2")) -> 46626 | L20: =NETWORKDAYS(J20,K20) -> 35 | M20: À faire
A21: 2.3 | B21: 2 | C21: Fantasy Barça | D21: Équipes fantasy, journées, classements, ligues. | E21: API-FANT, MOB-H | F21: Phase 1 (données matchs) | G21: Composition, scoring par journée, ligues. | H21: Calcul des points idempotent et testé sur matchs réels. | I21: =SUMIFS(Épopées!$G$6:$G$59,Épopées!$A$6:$A$59,"API-FANT|2")+SUMIFS(Épopées!$G$6:$G$59,Épopées!$A$6:$A$59,"MOB-H|2") -> 71.5 | J21: =MIN(SUMIFS(Épopées!$L$6:$L$59,Épopées!$A$6:$A$59,"API-FANT|2"),SUMIFS(Épopées!$L$6:$L$59,Épopées!$A$6:$A$59,"MOB-H|2")) -> 46596 | K21: =MAX(SUMIFS(Épopées!$M$6:$M$59,Épopées!$A$6:$A$59,"API-FANT|2"),SUMIFS(Épopées!$M$6:$M$59,Épopées!$A$6:$A$59,"MOB-H|2")) -> 46653 | L21: =NETWORKDAYS(J21,K21) -> 42 | M21: À faire
A22: 2.4 | B22: 2 | C22: Culé Passport | D22: Profil de gamification transverse. | E22: API-PASS, MOB-P | F22: 2.2, 2.3 | G22: XP, niveaux, badges, historique. | H22: Règles de badges validées. | I22: =SUMIFS(Épopées!$G$6:$G$59,Épopées!$A$6:$A$59,"API-PASS|2")+SUMIFS(Épopées!$G$6:$G$59,Épopées!$A$6:$A$59,"MOB-P|2") -> 54.5 | J22: =MIN(SUMIFS(Épopées!$L$6:$L$59,Épopées!$A$6:$A$59,"API-PASS|2"),SUMIFS(Épopées!$L$6:$L$59,Épopées!$A$6:$A$59,"MOB-P|2")) -> 46619 | K22: =MAX(SUMIFS(Épopées!$M$6:$M$59,Épopées!$A$6:$A$59,"API-PASS|2"),SUMIFS(Épopées!$M$6:$M$59,Épopées!$A$6:$A$59,"MOB-P|2")) -> 46710 | L22: =NETWORKDAYS(J22,K22) -> 66 | M22: À faire
A23: 2.5 | B23: 2 | C23: Durcissement plateforme | D23: Performance, sécurité et charge de la phase 2. | E23: API-PLAT | F23: Phase 2 (en continu) | G23: Index, caches, tests de charge étendus. | H23: Test de charge « soir de match » validé. | I23: =SUMIFS(Épopées!$G$6:$G$59,Épopées!$A$6:$A$59,"API-PLAT|2") -> 3 | J23: =MIN(SUMIFS(Épopées!$L$6:$L$59,Épopées!$A$6:$A$59,"API-PLAT|2")) -> 46643 | K23: =MAX(SUMIFS(Épopées!$M$6:$M$59,Épopées!$A$6:$A$59,"API-PLAT|2")) -> 46644 | L23: =NETWORKDAYS(J23,K23) -> 2 | M23: À faire
A24: 2.6 | B24: 2 | C24: Recette phase 2 | D24: Valider la version communautaire. | E24: Aucune épopée — durée fixe (Paramètres) | F24: 2.1 à 2.5 | G24: Rapport de recette phase 2. | H24: Critères §15.2 atteints. | I24: 0 | J24: =WORKDAY(MAX(K19,K20,K21,K22,K23),1) -> 46713 | K24: =WORKDAY(J24,Paramètres!$B$11-1) -> 46724 | L24: =NETWORKDAYS(J24,K24) -> 10 | M24: À faire
A25: 3.1 | B25: 3 | C25: La Masia Academy | D25: Académie fantasy. | E25: API-FANT, MOB-I | F25: Phase 2 (Fantasy) | G25: Joueurs d’académie, progression. | H25: Règles validées avec le porteur du projet. | I25: =SUMIFS(Épopées!$G$6:$G$59,Épopées!$A$6:$A$59,"API-FANT|3")+SUMIFS(Épopées!$G$6:$G$59,Épopées!$A$6:$A$59,"MOB-I|3") -> 34 | J25: =MIN(SUMIFS(Épopées!$L$6:$L$59,Épopées!$A$6:$A$59,"API-FANT|3"),SUMIFS(Épopées!$L$6:$L$59,Épopées!$A$6:$A$59,"MOB-I|3")) -> 46645 | K25: =MAX(SUMIFS(Épopées!$M$6:$M$59,Épopées!$A$6:$A$59,"API-FANT|3"),SUMIFS(Épopées!$M$6:$M$59,Épopées!$A$6:$A$59,"MOB-I|3")) -> 46727 | L25: =NETWORKDAYS(J25,K25) -> 59 | M25: À faire
A26: 3.2 | B26: 3 | C26: Wallpapers IA | D26: Génération d’images, galerie, partage. | E26: API-WALL, MOB-M | F26: Phase 1 (IA) | G26: Génération, file d’attente, modération des images, galerie. | H26: Aucun logo du club ; coûts maîtrisés. | I26: =SUMIFS(Épopées!$G$6:$G$59,Épopées!$A$6:$A$59,"API-WALL|3")+SUMIFS(Épopées!$G$6:$G$59,Épopées!$A$6:$A$59,"MOB-M|3") -> 52.25 | J26: =MIN(SUMIFS(Épopées!$L$6:$L$59,Épopées!$A$6:$A$59,"API-WALL|3"),SUMIFS(Épopées!$L$6:$L$59,Épopées!$A$6:$A$59,"MOB-M|3")) -> 46653 | K26: =MAX(SUMIFS(Épopées!$M$6:$M$59,Épopées!$A$6:$A$59,"API-WALL|3"),SUMIFS(Épopées!$M$6:$M$59,Épopées!$A$6:$A$59,"MOB-M|3")) -> 46748 | L26: =NETWORKDAYS(J26,K26) -> 68 | M26: À faire
A27: 3.3 | B27: 3 | C27: Évolutions admin phase 3 | D27: Compléments du back-office. | E27: ADM-WJ | F27: Phase 2 | G27: Écrans évolutions phase 3. | H27: Recette admin. | I27: =SUMIFS(Épopées!$G$6:$G$59,Épopées!$A$6:$A$59,"ADM-WJ|3") -> 6 | J27: =MIN(SUMIFS(Épopées!$L$6:$L$59,Épopées!$A$6:$A$59,"ADM-WJ|3")) -> 46673 | K27: =MAX(SUMIFS(Épopées!$M$6:$M$59,Épopées!$A$6:$A$59,"ADM-WJ|3")) -> 46679 | L27: =NETWORKDAYS(J27,K27) -> 5 | M27: À faire
A28: 3.4 | B28: 3 | C28: Recette finale, charge et mise en production | D28: Finaliser, mesurer et publier. | E28: Aucune épopée — durée fixe (Paramètres) | F28: 3.1 à 3.3 | G28: Campagne de charge finale, documentation, publication stores, tag de version production. | H28: Périmètre complet livré ; observabilité sans anomalie. | I28: 0 | J28: =WORKDAY(MAX(K25,K26,K27),1) -> 46749 | K28: =WORKDAY(J28,Paramètres!$B$11-1) -> 46762 | L28: =NETWORKDAYS(J28,K28) -> 10 | M28: À faire

Sheet Jalons
A1: Jalons du projet
A2: Dates calculées depuis le planning ; « Date réelle » et « Statut » sont à saisir au fil de l’eau.
A5: N° | B5: Jalon | C5: Phase | D5: Date prévue | E5: Critères de sortie (CDC §5.5 et §15.2) | F5: Date réelle | G5: Écart (jours) | H5: Statut
A6: M0 | B6: Lancement du projet (kick-off) | C6: 0 | D6: =Paramètres!$B$4 -> 46328 | E6: Secrets, environnements, projet GitHub et décisions « à confirmer » traités. | G6: =IF(F6="","",F6-D6) | H6: Terminé
A7: M1 | B7: Phase 0 terminée — socle opérationnel | C7: 0 | D7: =WORKDAY(_xlfn.MAXIFS(Épopées!$M$6:$M$59,Épopées!$E$6:$E$59,0),Paramètres!$B$11) -> 46449 | E7: Environnements opérationnels ; premier commit déployé en staging ; CI/CD verte ; design system implémenté (mobile + admin) ; observabilité de base. | G7: =IF(F7="","",F7-D7) | H7: À faire
A8: M2 | B8: Phase 1 terminée — MVP | C8: 1 | D8: =WORKDAY(_xlfn.MAXIFS(Épopées!$M$6:$M$59,Épopées!$E$6:$E$59,1),Paramètres!$B$11) -> 46629 | E8: Dashboard, jeux quotidiens, historique, calendrier + export agenda, assistant IA v1, admin de base ; version testable par un cercle restreint ; recette UAT validée ; aucune anomalie bloquante ; 48 h d’observation staging. | G8: =IF(F8="","",F8-D8) | H8: À faire
A9: M3 | B9: Phase 2 terminée — version communautaire | C9: 2 | D9: =WORKDAY(_xlfn.MAXIFS(Épopées!$M$6:$M$59,Épopées!$E$6:$E$59,2),Paramètres!$B$11) -> 46724 | E9: GOAT, Fantasy, carte communautaire et groupes, modération, Culé Passport ; test de charge « soir de match » ; revue RGPD de la géolocalisation. | G9: =IF(F9="","",F9-D9) | H9: À faire
A10: M4 | B10: Phase 3 terminée — périmètre complet | C10: 3 | D10: =WORKDAY(_xlfn.MAXIFS(Épopées!$M$6:$M$59,Épopées!$E$6:$E$59,3),Paramètres!$B$11) -> 46762 | E10: La Masia, Wallpapers IA, approfondissement IA ; recette finale ; campagne de charge finale ; documentation à jour ; publication sur les stores. | G10: =IF(F10="","",F10-D10) | H10: À faire
A12: Jalons intermédiaires par flux
A13: N° | B13: Jalon | C13: Phase | D13: Date prévue | E13: Contenu | F13: Date réelle | G13: Écart (jours) | H13: Statut
A14: API-P0 | B14: Fin du flux API — phase 0 | C14: 0 | D14: =_xlfn.MAXIFS(Épopées!$M$6:$M$59,Épopées!$E$6:$E$59,0,Épopées!$B$6:$B$59,"API") -> 46332 | E14: Toutes les épopées API de la phase 0 terminées (voir « Épopées »). | G14: =IF(F14="","",F14-D14) | H14: À faire
A15: API-P1 | B15: Fin du flux API — phase 1 | C15: 1 | D15: =_xlfn.MAXIFS(Épopées!$M$6:$M$59,Épopées!$E$6:$E$59,1,Épopées!$B$6:$B$59,"API") -> 46526 | E15: Toutes les épopées API de la phase 1 terminées (voir « Épopées »). | G15: =IF(F15="","",F15-D15) | H15: À faire
A16: API-P2 | B16: Fin du flux API — phase 2 | C16: 2 | D16: =_xlfn.MAXIFS(Épopées!$M$6:$M$59,Épopées!$E$6:$E$59,2,Épopées!$B$6:$B$59,"API") -> 46644 | E16: Toutes les épopées API de la phase 2 terminées (voir « Épopées »). | G16: =IF(F16="","",F16-D16) | H16: À faire
A17: API-P3 | B17: Fin du flux API — phase 3 | C17: 3 | D17: =_xlfn.MAXIFS(Épopées!$M$6:$M$59,Épopées!$E$6:$E$59,3,Épopées!$B$6:$B$59,"API") -> 46667 | E17: Toutes les épopées API de la phase 3 terminées (voir « Épopées »). | G17: =IF(F17="","",F17-D17) | H17: À faire
A18: MOB-P0 | B18: Fin du flux Mobile — phase 0 | C18: 0 | D18: =_xlfn.MAXIFS(Épopées!$M$6:$M$59,Épopées!$E$6:$E$59,0,Épopées!$B$6:$B$59,"Mobile") -> 46435 | E18: Toutes les épopées Mobile de la phase 0 terminées (voir « Épopées »). | G18: =IF(F18="","",F18-D18) | H18: À faire
A19: MOB-P1 | B19: Fin du flux Mobile — phase 1 | C19: 1 | D19: =_xlfn.MAXIFS(Épopées!$M$6:$M$59,Épopées!$E$6:$E$59,1,Épopées!$B$6:$B$59,"Mobile") -> 46615 | E19: Toutes les épopées Mobile de la phase 1 terminées (voir « Épopées »). | G19: =IF(F19="","",F19-D19) | H19: À faire
A20: MOB-P2 | B20: Fin du flux Mobile — phase 2 | C20: 2 | D20: =_xlfn.MAXIFS(Épopées!$M$6:$M$59,Épopées!$E$6:$E$59,2,Épopées!$B$6:$B$59,"Mobile") -> 46710 | E20: Toutes les épopées Mobile de la phase 2 terminées (voir « Épopées »). | G20: =IF(F20="","",F20-D20) | H20: À faire
A21: MOB-P3 | B21: Fin du flux Mobile — phase 3 | C21: 3 | D21: =_xlfn.MAXIFS(Épopées!$M$6:$M$59,Épopées!$E$6:$E$59,3,Épopées!$B$6:$B$59,"Mobile") -> 46748 | E21: Toutes les épopées Mobile de la phase 3 terminées (voir « Épopées »). | G21: =IF(F21="","",F21-D21) | H21: À faire
A22: ADM-P0 | B22: Fin du flux Admin — phase 0 | C22: 0 | D22: =_xlfn.MAXIFS(Épopées!$M$6:$M$59,Épopées!$E$6:$E$59,0,Épopées!$B$6:$B$59,"Admin") -> 46387 | E22: Toutes les épopées Admin de la phase 0 terminées (voir « Épopées »). | G22: =IF(F22="","",F22-D22) | H22: À faire
A23: ADM-P1 | B23: Fin du flux Admin — phase 1 | C23: 1 | D23: =_xlfn.MAXIFS(Épopées!$M$6:$M$59,Épopées!$E$6:$E$59,1,Épopées!$B$6:$B$59,"Admin") -> 46573 | E23: Toutes les épopées Admin de la phase 1 terminées (voir « Épopées »). | G23: =IF(F23="","",F23-D23) | H23: À faire
A24: ADM-P2 | B24: Fin du flux Admin — phase 2 | C24: 2 | D24: =_xlfn.MAXIFS(Épopées!$M$6:$M$59,Épopées!$E$6:$E$59,2,Épopées!$B$6:$B$59,"Admin") -> 46609 | E24: Toutes les épopées Admin de la phase 2 terminées (voir « Épopées »). | G24: =IF(F24="","",F24-D24) | H24: À faire
A25: ADM-P3 | B25: Fin du flux Admin — phase 3 | C25: 3 | D25: =_xlfn.MAXIFS(Épopées!$M$6:$M$59,Épopées!$E$6:$E$59,3,Épopées!$B$6:$B$59,"Admin") -> 46679 | E25: Toutes les épopées Admin de la phase 3 terminées (voir « Épopées »). | G25: =IF(F25="","",F25-D25) | H25: À faire

Sheet Gantt
A1: Diagramme de Gantt (par semaine)
A2: Barres colorées par phase, calculées depuis « Épopées ». Trait rouge = semaine en cours. Ligne ◆ = jalons de fin de phase.
A5: Flux | B5: Épopée | C5: Intitulé | D5: Phase | E5: Début | F5: Fin | G5: Avancement | H5: =Paramètres!$B$4-WEEKDAY(Paramètres!$B$4,2)+1 -> 46328 | I5: =H5+7 -> 46335 | J5: =I5+7 -> 46342 | K5: =J5+7 -> 46349 | L5: =K5+7 -> 46356 | M5: =L5+7 -> 46363 | N5: =M5+7 -> 46370 | O5: =N5+7 -> 46377 | P5: =O5+7 -> 46384 | ... CS5: =CR5+7 -> 46951
A6: =Épopées!B6 -> API | B6: =Épopées!C6 -> API-PLAT | C6: =Épopées!D6 -> Plateforme, qualité, performance et exploitation | D6: =Épopées!E6 -> 0 | E6: =Épopées!L6 -> 46328 | F6: =Épopées!M6 -> 46331 | G6: =Épopées!O6 -> 0
A7: =Épopées!B7 -> API | B7: =Épopées!C7 -> API-AUTH | C7: =Épopées!D7 -> Identité, authentification, comptes et RGPD | D7: =Épopées!E7 -> 0 | E7: =Épopées!L7 -> 46332 | F7: =Épopées!M7 -> 46332 | G7: =Épopées!O7 -> 0
A8: =Épopées!B8 -> API | B8: =Épopées!C8 -> API-PLAT | C8: =Épopées!D8 -> Plateforme, qualité, performance et exploitation | D8: =Épopées!E8 -> 1 | E8: =Épopées!L8 -> 46335 | F8: =Épopées!M8 -> 46363 | G8: =Épopées!O8 -> 0
A9: =Épopées!B9 -> API | B9: =Épopées!C9 -> API-AUTH | C9: =Épopées!D9 -> Identité, authentification, comptes et RGPD | D9: =Épopées!E9 -> 1 | E9: =Épopées!L9 -> 46364 | F9: =Épopées!M9 -> 46398 | G9: =Épopées!O9 -> 0
A10: =Épopées!B10 -> API | B10: =Épopées!C10 -> API-FOOT | C10: =Épopées!D10 -> Données football et contenu éditorial | D10: =Épopées!E10 -> 1 | E10: =Épopées!L10 -> 46399 | F10: =Épopées!M10 -> 46440 | G10: =Épopées!O10 -> 0
A11: =Épopées!B11 -> API | B11: =Épopées!C11 -> API-CAL | C11: =Épopées!D11 -> Calendrier et export agenda | D11: =Épopées!E11 -> 1 | E11: =Épopées!L11 -> 46441 | F11: =Épopées!M11 -> 46451 | G11: =Épopées!O11 -> 0
A12: =Épopées!B12 -> API | B12: =Épopées!C12 -> API-JEUX | C12: =Épopées!D12 -> Guess the Player & Quiz adaptatif | D12: =Épopées!E12 -> 1 | E12: =Épopées!L12 -> 46454 | F12: =Épopées!M12 -> 46484 | G12: =Épopées!O12 -> 0
A13: =Épopées!B13 -> API | B13: =Épopées!C13 -> API-NOTIF | C13: =Épopées!D13 -> Notifications push et centre de notifications | D13: =Épopées!E13 -> 1 | E13: =Épopées!L13 -> 46485 | F13: =Épopées!M13 -> 46505 | G13: =Épopées!O13 -> 0
A14: =Épopées!B14 -> API | B14: =Épopées!C14 -> API-IA | C14: =Épopées!D14 -> Assistant IA Barça AI | D14: =Épopées!E14 -> 1 | E14: =Épopées!L14 -> 46506 | F14: =Épopées!M14 -> 46526 | G14: =Épopées!O14 -> 0
A15: =Épopées!B15 -> API | B15: =Épopées!C15 -> API-COMM | C15: =Épopées!D15 -> Carte communautaire et groupes locaux | D15: =Épopées!E15 -> 2 | E15: =Épopées!L15 -> 46527 | F15: =Épopées!M15 -> 46552 | G15: =Épopées!O15 -> 0
A16: =Épopées!B16 -> API | B16: =Épopées!C16 -> API-MODER | C16: =Épopées!D16 -> Modération et sécurité communautaire | D16: =Épopées!E16 -> 2 | E16: =Épopées!L16 -> 46553 | F16: =Épopées!M16 -> 46577 | G16: =Épopées!O16 -> 0
A17: =Épopées!B17 -> API | B17: =Épopées!C17 -> API-GOAT | C17: =Épopées!D17 -> Comparateur GOAT et votes | D17: =Épopées!E17 -> 2 | E17: =Épopées!L17 -> 46580 | F17: =Épopées!M17 -> 46595 | G17: =Épopées!O17 -> 0
... A59: =Épopées!B59 -> Admin | B59: =Épopées!C59 -> ADM-WJ | C59: =Épopées!D59 -> Utilisateurs et évolutions phase 2-3 | D59: =Épopées!E59 -> 3 | E59: =Épopées!L59 -> 46673 | F59: =Épopées!M59 -> 46679 | G59: =Épopées!O59 -> 0
C61: Jalons (fin de phase + recette) | H61: =IF(OR(AND(Jalons!$D$7>=H$5,Jalons!$D$7<H$5+7),AND(Jalons!$D$8>=H$5,Jalons!$D$8<H$5+7),AND(Jalons!$D$9>=H$5,Jalons!$D$9<H$5+7),AND(Jalons!$D$10>=H$5,Jalons!$D$10<H$5+7)),"◆","") | I61: =IF(OR(AND(Jalons!$D$7>=I$5,Jalons!$D$7<I$5+7),AND(Jalons!$D$8>=I$5,Jalons!$D$8<I$5+7),AND(Jalons!$D$9>=I$5,Jalons!$D$9<I$5+7),AND(Jalons!$D$10>=I$5,Jalons!$D$10<I$5+7)),"◆","") | J61: =IF(OR(AND(Jalons!$D$7>=J$5,Jalons!$D$7<J$5+7),AND(Jalons!$D$8>=J$5,Jalons!$D$8<J$5+7),AND(Jalons!$D$9>=J$5,Jalons!$D$9<J$5+7),AND(Jalons!$D$10>=J$5,Jalons!$D$10<J$5+7)),"◆","") | K61: =IF(OR(AND(Jalons!$D$7>=K$5,Jalons!$D$7<K$5+7),AND(Jalons!$D$8>=K$5,Jalons!$D$8<K$5+7),AND(Jalons!$D$9>=K$5,Jalons!$D$9<K$5+7),AND(Jalons!$D$10>=K$5,Jalons!$D$10<K$5+7)),"◆","") | L61: =IF(OR(AND(Jalons!$D$7>=L$5,Jalons!$D$7<L$5+7),AND(Jalons!$D$8>=L$5,Jalons!$D$8<L$5+7),AND(Jalons!$D$9>=L$5,Jalons!$D$9<L$5+7),AND(Jalons!$D$10>=L$5,Jalons!$D$10<L$5+7)),"◆","") | M61: =IF(OR(AND(Jalons!$D$7>=M$5,Jalons!$D$7<M$5+7),AND(Jalons!$D$8>=M$5,Jalons!$D$8<M$5+7),AND(Jalons!$D$9>=M$5,Jalons!$D$9<M$5+7),AND(Jalons!$D$10>=M$5,Jalons!$D$10<M$5+7)),"◆","") | N61: =IF(OR(AND(Jalons!$D$7>=N$5,Jalons!$D$7<N$5+7),AND(Jalons!$D$8>=N$5,Jalons!$D$8<N$5+7),AND(Jalons!$D$9>=N$5,Jalons!$D$9<N$5+7),AND(Jalons!$D$10>=N$5,Jalons!$D$10<N$5+7)),"◆","") | O61: =IF(OR(AND(Jalons!$D$7>=O$5,Jalons!$D$7<O$5+7),AND(Jalons!$D$8>=O$5,Jalons!$D$8<O$5+7),AND(Jalons!$D$9>=O$5,Jalons!$D$9<O$5+7),AND(Jalons!$D$10>=O$5,Jalons!$D$10<O$5+7)),"◆","") | ... CS61: =IF(OR(AND(Jalons!$D$7>=CS$5,Jalons!$D$7<CS$5+7),AND(Jalons!$D$8>=CS$5,Jalons!$D$8<CS$5+7),AND(Jalons!$D$9>=CS$5,Jalons!$D$9<CS$5+7),AND(Jalons!$D$10>=CS$5,Jalons!$D$10<CS$5+7)),"◆","")

Sheet Épopées
A1: Plan par épopée (flux × phase)
A2: Durée = charge × (1 + marge) ÷ (développeurs × focus). Début = max(fin de l’épopée précédente du flux, porte de phase). Tout est recalculé depuis « Paramètres ».
A5: Clé | B5: Flux | C5: Épopée | D5: Intitulé | E5: Phase | F5: Nb issues | G5: Charge (j) | H5: Devs | I5: Durée (jo) | J5: Porte de phase | K5: Semaines | L5: Début | M5: Fin | N5: Terminées | O5: % avancement | P5: Statut
A6: API-PLAT|0 | B6: API | C6: API-PLAT | D6: Plateforme, qualité, performance et exploitation | E6: 0 | F6: =COUNTIFS(Backlog!$K$6:$K$1327,A6) -> 10 | G6: =SUMIFS(Backlog!$I$6:$I$1327,Backlog!$K$6:$K$1327,A6) -> 6.75 | H6: =IF(B6="API",Paramètres!$B$7,IF(B6="Mobile",Paramètres!$B$8,Paramètres!$B$9)) -> 3 | I6: =MAX(1,ROUNDUP(G6*(1+Paramètres!$B$6)/(H6*Paramètres!$B$5),0)) -> 4 | J6: =Paramètres!$B$4 -> 46328 | K6: =ROUNDUP(I6/5,0) -> 1 | L6: =J6 -> 46328 | M6: =WORKDAY(L6,I6-1) -> 46331 | N6: =COUNTIFS(Backlog!$K$6:$K$1327,A6,Backlog!$O$6:$O$1327,"Terminé") -> 0 | O6: =IF(F6=0,0,N6/F6) -> 0 | P6: =IF(O6=1,"Terminé",IF(OR(O6>0,COUNTIFS(Backlog!$K$6:$K$1327,A6,Backlog!$O$6:$O$1327,"En cours")>0),"En cours","À faire")) -> À faire
A7: API-AUTH|0 | B7: API | C7: API-AUTH | D7: Identité, authentification, comptes et RGPD | E7: 0 | F7: =COUNTIFS(Backlog!$K$6:$K$1327,A7) -> 2 | G7: =SUMIFS(Backlog!$I$6:$I$1327,Backlog!$K$6:$K$1327,A7) -> 2 | H7: =IF(B7="API",Paramètres!$B$7,IF(B7="Mobile",Paramètres!$B$8,Paramètres!$B$9)) -> 3 | I7: =MAX(1,ROUNDUP(G7*(1+Paramètres!$B$6)/(H7*Paramètres!$B$5),0)) -> 1 | J7: =Paramètres!$B$4 -> 46328 | K7: =ROUNDUP(I7/5,0) -> 1 | L7: =MAX(J7,WORKDAY(M6,1)) -> 46332 | M7: =WORKDAY(L7,I7-1) -> 46332 | N7: =COUNTIFS(Backlog!$K$6:$K$1327,A7,Backlog!$O$6:$O$1327,"Terminé") -> 0 | O7: =IF(F7=0,0,N7/F7) -> 0 | P7: =IF(O7=1,"Terminé",IF(OR(O7>0,COUNTIFS(Backlog!$K$6:$K$1327,A7,Backlog!$O$6:$O$1327,"En cours")>0),"En cours","À faire")) -> À faire
A8: API-PLAT|1 | B8: API | C8: API-PLAT | D8: Plateforme, qualité, performance et exploitation | E8: 1 | F8: =COUNTIFS(Backlog!$K$6:$K$1327,A8) -> 43 | G8: =SUMIFS(Backlog!$I$6:$I$1327,Backlog!$K$6:$K$1327,A8) -> 42 | H8: =IF(B8="API",Paramètres!$B$7,IF(B8="Mobile",Paramètres!$B$8,Paramètres!$B$9)) -> 3 | I8: =MAX(1,ROUNDUP(G8*(1+Paramètres!$B$6)/(H8*Paramètres!$B$5),0)) -> 21 | J8: =Paramètres!$B$4 -> 46328 | K8: =ROUNDUP(I8/5,0) -> 5 | L8: =MAX(J8,WORKDAY(M7,1)) -> 46335 | M8: =WORKDAY(L8,I8-1) -> 46363 | N8: =COUNTIFS(Backlog!$K$6:$K$1327,A8,Backlog!$O$6:$O$1327,"Terminé") -> 0 | O8: =IF(F8=0,0,N8/F8) -> 0 | P8: =IF(O8=1,"Terminé",IF(OR(O8>0,COUNTIFS(Backlog!$K$6:$K$1327,A8,Backlog!$O$6:$O$1327,"En cours")>0),"En cours","À faire")) -> À faire
A9: API-AUTH|1 | B9: API | C9: API-AUTH | D9: Identité, authentification, comptes et RGPD | E9: 1 | F9: =COUNTIFS(Backlog!$K$6:$K$1327,A9) -> 43 | G9: =SUMIFS(Backlog!$I$6:$I$1327,Backlog!$K$6:$K$1327,A9) -> 51 | H9: =IF(B9="API",Paramètres!$B$7,IF(B9="Mobile",Paramètres!$B$8,Paramètres!$B$9)) -> 3 | I9: =MAX(1,ROUNDUP(G9*(1+Paramètres!$B$6)/(H9*Paramètres!$B$5),0)) -> 25 | J9: =Paramètres!$B$4 -> 46328 | K9: =ROUNDUP(I9/5,0) -> 5 | L9: =MAX(J9,WORKDAY(M8,1)) -> 46364 | M9: =WORKDAY(L9,I9-1) -> 46398 | N9: =COUNTIFS(Backlog!$K$6:$K$1327,A9,Backlog!$O$6:$O$1327,"Terminé") -> 0 | O9: =IF(F9=0,0,N9/F9) -> 0 | P9: =IF(O9=1,"Terminé",IF(OR(O9>0,COUNTIFS(Backlog!$K$6:$K$1327,A9,Backlog!$O$6:$O$1327,"En cours")>0),"En cours","À faire")) -> À faire
A10: API-FOOT|1 | B10: API | C10: API-FOOT | D10: Données football et contenu éditorial | E10: 1 | F10: =COUNTIFS(Backlog!$K$6:$K$1327,A10) -> 56 | G10: =SUMIFS(Backlog!$I$6:$I$1327,Backlog!$K$6:$K$1327,A10) -> 61.5 | H10: =IF(B10="API",Paramètres!$B$7,IF(B10="Mobile",Paramètres!$B$8,Paramètres!$B$9)) -> 3 | I10: =MAX(1,ROUNDUP(G10*(1+Paramètres!$B$6)/(H10*Paramètres!$B$5),0)) -> 30 | J10: =Paramètres!$B$4 -> 46328 | K10: =ROUNDUP(I10/5,0) -> 6 | L10: =MAX(J10,WORKDAY(M9,1)) -> 46399 | M10: =WORKDAY(L10,I10-1) -> 46440 | N10: =COUNTIFS(Backlog!$K$6:$K$1327,A10,Backlog!$O$6:$O$1327,"Terminé") -> 0 | O10: =IF(F10=0,0,N10/F10) -> 0 | P10: =IF(O10=1,"Terminé",IF(OR(O10>0,COUNTIFS(Backlog!$K$6:$K$1327,A10,Backlog!$O$6:$O$1327,"En cours")>0),"En cours","À faire")) -> À faire
A11: API-CAL|1 | B11: API | C11: API-CAL | D11: Calendrier et export agenda | E11: 1 | F11: =COUNTIFS(Backlog!$K$6:$K$1327,A11) -> 24 | G11: =SUMIFS(Backlog!$I$6:$I$1327,Backlog!$K$6:$K$1327,A11) -> 18 | H11: =IF(B11="API",Paramètres!$B$7,IF(B11="Mobile",Paramètres!$B$8,Paramètres!$B$9)) -> 3 | I11: =MAX(1,ROUNDUP(G11*(1+Paramètres!$B$6)/(H11*Paramètres!$B$5),0)) -> 9 | J11: =Paramètres!$B$4 -> 46328 | K11: =ROUNDUP(I11/5,0) -> 2 | L11: =MAX(J11,WORKDAY(M10,1)) -> 46441 | M11: =WORKDAY(L11,I11-1) -> 46451 | N11: =COUNTIFS(Backlog!$K$6:$K$1327,A11,Backlog!$O$6:$O$1327,"Terminé") -> 0 | O11: =IF(F11=0,0,N11/F11) -> 0 | P11: =IF(O11=1,"Terminé",IF(OR(O11>0,COUNTIFS(Backlog!$K$6:$K$1327,A11,Backlog!$O$6:$O$1327,"En cours")>0),"En cours","À faire")) -> À faire
A12: API-JEUX|1 | B12: API | C12: API-JEUX | D12: Guess the Player & Quiz adaptatif | E12: 1 | F12: =COUNTIFS(Backlog!$K$6:$K$1327,A12) -> 37 | G12: =SUMIFS(Backlog!$I$6:$I$1327,Backlog!$K$6:$K$1327,A12) -> 48 | H12: =IF(B12="API",Paramètres!$B$7,IF(B12="Mobile",Paramètres!$B$8,Paramètres!$B$9)) -> 3 | I12: =MAX(1,ROUNDUP(G12*(1+Paramètres!$B$6)/(H12*Paramètres!$B$5),0)) -> 23 | J12: =Paramètres!$B$4 -> 46328 | K12: =ROUNDUP(I12/5,0) -> 5 | L12: =MAX(J12,WORKDAY(M11,1)) -> 46454 | M12: =WORKDAY(L12,I12-1) -> 46484 | N12: =COUNTIFS(Backlog!$K$6:$K$1327,A12,Backlog!$O$6:$O$1327,"Terminé") -> 0 | O12: =IF(F12=0,0,N12/F12) -> 0 | P12: =IF(O12=1,"Terminé",IF(OR(O12>0,COUNTIFS(Backlog!$K$6:$K$1327,A12,Backlog!$O$6:$O$1327,"En cours")>0),"En cours","À faire")) -> À faire
A13: API-NOTIF|1 | B13: API | C13: API-NOTIF | D13: Notifications push et centre de notifications | E13: 1 | F13: =COUNTIFS(Backlog!$K$6:$K$1327,A13) -> 31 | G13: =SUMIFS(Backlog!$I$6:$I$1327,Backlog!$K$6:$K$1327,A13) -> 30 | H13: =IF(B13="API",Paramètres!$B$7,IF(B13="Mobile",Paramètres!$B$8,Paramètres!$B$9)) -> 3 | I13: =MAX(1,ROUNDUP(G13*(1+Paramètres!$B$6)/(H13*Paramètres!$B$5),0)) -> 15 | J13: =Paramètres!$B$4 -> 46328 | K13: =ROUNDUP(I13/5,0) -> 3 | L13: =MAX(J13,WORKDAY(M12,1)) -> 46485 | M13: =WORKDAY(L13,I13-1) -> 46505 | N13: =COUNTIFS(Backlog!$K$6:$K$1327,A13,Backlog!$O$6:$O$1327,"Terminé") -> 0 | O13: =IF(F13=0,0,N13/F13) -> 0 | P13: =IF(O13=1,"Terminé",IF(OR(O13>0,COUNTIFS(Backlog!$K$6:$K$1327,A13,Backlog!$O$6:$O$1327,"En cours")>0),"En cours","À faire")) -> À faire
A14: API-IA|1 | B14: API | C14: API-IA | D14: Assistant IA Barça AI | E14: 1 | F14: =COUNTIFS(Backlog!$K$6:$K$1327,A14) -> 34 | G14: =SUMIFS(Backlog!$I$6:$I$1327,Backlog!$K$6:$K$1327,A14) -> 30.5 | H14: =IF(B14="API",Paramètres!$B$7,IF(B14="Mobile",Paramètres!$B$8,Paramètres!$B$9)) -> 3 | I14: =MAX(1,ROUNDUP(G14*(1+Paramètres!$B$6)/(H14*Paramètres!$B$5),0)) -> 15 | J14: =Paramètres!$B$4 -> 46328 | K14: =ROUNDUP(I14/5,0) -> 3 | L14: =MAX(J14,WORKDAY(M13,1)) -> 46506 | M14: =WORKDAY(L14,I14-1) -> 46526 | N14: =COUNTIFS(Backlog!$K$6:$K$1327,A14,Backlog!$O$6:$O$1327,"Terminé") -> 0 | O14: =IF(F14=0,0,N14/F14) -> 0 | P14: =IF(O14=1,"Terminé",IF(OR(O14>0,COUNTIFS(Backlog!$K$6:$K$1327,A14,Backlog!$O$6:$O$1327,"En cours")>0),"En cours","À faire")) -> À faire
A15: API-COMM|2 | B15: API | C15: API-COMM | D15: Carte communautaire et groupes locaux | E15: 2 | F15: =COUNTIFS(Backlog!$K$6:$K$1327,A15) -> 33 | G15: =SUMIFS(Backlog!$I$6:$I$1327,Backlog!$K$6:$K$1327,A15) -> 36 | H15: =IF(B15="API",Paramètres!$B$7,IF(B15="Mobile",Paramètres!$B$8,Paramètres!$B$9)) -> 3 | I15: =MAX(1,ROUNDUP(G15*(1+Paramètres!$B$6)/(H15*Paramètres!$B$5),0)) -> 18 | J15: =Paramètres!$B$4 -> 46328 | K15: =ROUNDUP(I15/5,0) -> 4 | L15: =MAX(J15,WORKDAY(M14,1)) -> 46527 | M15: =WORKDAY(L15,I15-1) -> 46552 | N15: =COUNTIFS(Backlog!$K$6:$K$1327,A15,Backlog!$O$6:$O$1327,"Terminé") -> 0 | O15: =IF(F15=0,0,N15/F15) -> 0 | P15: =IF(O15=1,"Terminé",IF(OR(O15>0,COUNTIFS(Backlog!$K$6:$K$1327,A15,Backlog!$O$6:$O$1327,"En cours")>0),"En cours","À faire")) -> À faire
A16: API-MODER|2 | B16: API | C16: API-MODER | D16: Modération et sécurité communautaire | E16: 2 | F16: =COUNTIFS(Backlog!$K$6:$K$1327,A16) -> 32 | G16: =SUMIFS(Backlog!$I$6:$I$1327,Backlog!$K$6:$K$1327,A16) -> 38.5 | H16: =IF(B16="API",Paramètres!$B$7,IF(B16="Mobile",Paramètres!$B$8,Paramètres!$B$9)) -> 3 | I16: =MAX(1,ROUNDUP(G16*(1+Paramètres!$B$6)/(H16*Paramètres!$B$5),0)) -> 19 | J16: =Paramètres!$B$4 -> 46328 | K16: =ROUNDUP(I16/5,0) -> 4 | L16: =MAX(J16,WORKDAY(M15,1)) -> 46553 | M16: =WORKDAY(L16,I16-1) -> 46577 | N16: =COUNTIFS(Backlog!$K$6:$K$1327,A16,Backlog!$O$6:$O$1327,"Terminé") -> 0 | O16: =IF(F16=0,0,N16/F16) -> 0 | P16: =IF(O16=1,"Terminé",IF(OR(O16>0,COUNTIFS(Backlog!$K$6:$K$1327,A16,Backlog!$O$6:$O$1327,"En cours")>0),"En cours","À faire")) -> À faire
A17: API-GOAT|2 | B17: API | C17: API-GOAT | D17: Comparateur GOAT et votes | E17: 2 | F17: =COUNTIFS(Backlog!$K$6:$K$1327,A17) -> 26 | G17: =SUMIFS(Backlog!$I$6:$I$1327,Backlog!$K$6:$K$1327,A17) -> 25 | H17: =IF(B17="API",Paramètres!$B$7,IF(B17="Mobile",Paramètres!$B$8,Paramètres!$B$9)) -> 3 | I17: =MAX(1,ROUNDUP(G17*(1+Paramètres!$B$6)/(H17*Paramètres!$B$5),0)) -> 12 | J17: =Paramètres!$B$4 -> 46328 | K17: =ROUNDUP(I17/5,0) -> 3 | L17: =MAX(J17,WORKDAY(M16,1)) -> 46580 | M17: =WORKDAY(L17,I17-1) -> 46595 | N17: =COUNTIFS(Backlog!$K$6:$K$1327,A17,Backlog!$O$6:$O$1327,"Terminé") -> 0 | O17: =IF(F17=0,0,N17/F17) -> 0 | P17: =IF(O17=1,"Terminé",IF(OR(O17>0,COUNTIFS(Backlog!$K$6:$K$1327,A17,Backlog!$O$6:$O$1327,"En cours")>0),"En cours","À faire")) -> À faire
A18: API-FANT|2 | B18: API | C18: API-FANT | D18: Fantasy Barça et La Masia Academy | E18: 2 | F18: =COUNTIFS(Backlog!$K$6:$K$1327,A18) -> 24 | G18: =SUMIFS(Backlog!$I$6:$I$1327,Backlog!$K$6:$K$1327,A18) -> 33.5 | H18: =IF(B18="API",Paramètres!$B$7,IF(B18="Mobile",Paramètres!$B$8,Paramètres!$B$9)) -> 3 | I18: =MAX(1,ROUNDUP(G18*(1+Paramètres!$B$6)/(H18*Paramètres!$B$5),0)) -> 17 | J18: =Paramètres!$B$4 -> 46328 | K18: =ROUNDUP(I18/5,0) -> 4 | L18: =MAX(J18,WORKDAY(M17,1)) -> 46596 | M18: =WORKDAY(L18,I18-1) -> 46618 | N18: =COUNTIFS(Backlog!$K$6:$K$1327,A18,Backlog!$O$6:$O$1327,"Terminé") -> 0 | O18: =IF(F18=0,0,N18/F18) -> 0 | P18: =IF(O18=1,"Terminé",IF(OR(O18>0,COUNTIFS(Backlog!$K$6:$K$1327,A18,Backlog!$O$6:$O$1327,"En cours")>0),"En cours","À faire")) -> À faire
... A22: API-WALL|3 | B22: API | C22: API-WALL | D22: Wallpapers IA | E22: 3 | F22: =COUNTIFS(Backlog!$K$6:$K$1327,A22) -> 31 | G22: =SUMIFS(Backlog!$I$6:$I$1327,Backlog!$K$6:$K$1327,A22) -> 22.75 | H22: =IF(B22="API",Paramètres!$B$7,IF(B22="Mobile",Paramètres!$B$8,Paramètres!$B$9)) -> 3 | I22: =MAX(1,ROUNDUP(G22*(1+Paramètres!$B$6)/(H22*Paramètres!$B$5),0)) -> 11 | J22: =Paramètres!$B$4 -> 46328 | K22: =ROUNDUP(I22/5,0) -> 3 | L22: =MAX(J22,WORKDAY(M21,1)) -> 46653 | M22: =WORKDAY(L22,I22-1) -> 46667 | N22: =COUNTIFS(Backlog!$K$6:$K$1327,A22,Backlog!$O$6:$O$1327,"Terminé") -> 0 | O22: =IF(F22=0,0,N22/F22) -> 0 | P22: =IF(O22=1,"Terminé",IF(OR(O22>0,COUNTIFS(Backlog!$K$6:$K$1327,A22,Backlog!$O$6:$O$1327,"En cours")>0),"En cours","À faire")) -> À faire
A23: MOB-FND|0 | B23: Mobile | C23: MOB-FND | D23: Socle technique Flutter | E23: 0 | F23: =COUNTIFS(Backlog!$K$6:$K$1327,A23) -> 47 | G23: =SUMIFS(Backlog!$I$6:$I$1327,Backlog!$K$6:$K$1327,A23) -> 50.25 | H23: =IF(B23="API",Paramètres!$B$7,IF(B23="Mobile",Paramètres!$B$8,Paramètres!$B$9)) -> 3 | I23: =MAX(1,ROUNDUP(G23*(1+Paramètres!$B$6)/(H23*Paramètres!$B$5),0)) -> 25 | J23: =Paramètres!$B$4 -> 46328 | K23: =ROUNDUP(I23/5,0) -> 5 | L23: =J23 -> 46328 | M23: =WORKDAY(L23,I23-1) -> 46360 | N23: =COUNTIFS(Backlog!$K$6:$K$1327,A23,Backlog!$O$6:$O$1327,"Terminé") -> 0 | O23: =IF(F23=0,0,N23/F23) -> 0 | P23: =IF(O23=1,"Terminé",IF(OR(O23>0,COUNTIFS(Backlog!$K$6:$K$1327,A23,Backlog!$O$6:$O$1327,"En cours")>0),"En cours","À faire")) -> À faire
A24: MOB-ZA|0 | B24: Mobile | C24: MOB-ZA | D24: Fondations | E24: 0 | F24: =COUNTIFS(Backlog!$K$6:$K$1327,A24) -> 16 | G24: =SUMIFS(Backlog!$I$6:$I$1327,Backlog!$K$6:$K$1327,A24) -> 14.5 | H24: =IF(B24="API",Paramètres!$B$7,IF(B24="Mobile",Paramètres!$B$8,Paramètres!$B$9)) -> 3 | I24: =MAX(1,ROUNDUP(G24*(1+Paramètres!$B$6)/(H24*Paramètres!$B$5),0)) -> 7 | J24: =Paramètres!$B$4 -> 46328 | K24: =ROUNDUP(I24/5,0) -> 2 | L24: =MAX(J24,WORKDAY(M23,1)) -> 46363 | M24: =WORKDAY(L24,I24-1) -> 46371 | N24: =COUNTIFS(Backlog!$K$6:$K$1327,A24,Backlog!$O$6:$O$1327,"Terminé") -> 0 | O24: =IF(F24=0,0,N24/F24) -> 0 | P24: =IF(O24=1,"Terminé",IF(OR(O24>0,COUNTIFS(Backlog!$K$6:$K$1327,A24,Backlog!$O$6:$O$1327,"En cours")>0),"En cours","À faire")) -> À faire
A25: MOB-ZB|0 | B25: Mobile | C25: MOB-ZB | D25: Composants de base | E25: 0 | F25: =COUNTIFS(Backlog!$K$6:$K$1327,A25) -> 18 | G25: =SUMIFS(Backlog!$I$6:$I$1327,Backlog!$K$6:$K$1327,A25) -> 21 | H25: =IF(B25="API",Paramètres!$B$7,IF(B25="Mobile",Paramètres!$B$8,Paramètres!$B$9)) -> 3 | I25: =MAX(1,ROUNDUP(G25*(1+Paramètres!$B$6)/(H25*Paramètres!$B$5),0)) -> 11 | J25: =Paramètres!$B$4 -> 46328 | K25: =ROUNDUP(I25/5,0) -> 3 | L25: =MAX(J25,WORKDAY(M24,1)) -> 46372 | M25: =WORKDAY(L25,I25-1) -> 46386 | N25: =COUNTIFS(Backlog!$K$6:$K$1327,A25,Backlog!$O$6:$O$1327,"Terminé") -> 0 | O25: =IF(F25=0,0,N25/F25) -> 0 | P25: =IF(O25=1,"Terminé",IF(OR(O25>0,COUNTIFS(Backlog!$K$6:$K$1327,A25,Backlog!$O$6:$O$1327,"En cours")>0),"En cours","À faire")) -> À faire
A26: MOB-ZC|0 | B26: Mobile | C26: MOB-ZC | D26: Retours et états | E26: 0 | F26: =COUNTIFS(Backlog!$K$6:$K$1327,A26) -> 17 | G26: =SUMIFS(Backlog!$I$6:$I$1327,Backlog!$K$6:$K$1327,A26) -> 18 | H26: =IF(B26="API",Paramètres!$B$7,IF(B26="Mobile",Paramètres!$B$8,Paramètres!$B$9)) -> 3 | I26: =MAX(1,ROUNDUP(G26*(1+Paramètres!$B$6)/(H26*Paramètres!$B$5),0)) -> 9 | J26: =Paramètres!$B$4 -> 46328 | K26: =ROUNDUP(I26/5,0) -> 2 | L26: =MAX(J26,WORKDAY(M25,1)) -> 46387 | M26: =WORKDAY(L26,I26-1) -> 46399 | N26: =COUNTIFS(Backlog!$K$6:$K$1327,A26,Backlog!$O$6:$O$1327,"Terminé") -> 0 | O26: =IF(F26=0,0,N26/F26) -> 0 | P26: =IF(O26=1,"Terminé",IF(OR(O26>0,COUNTIFS(Backlog!$K$6:$K$1327,A26,Backlog!$O$6:$O$1327,"En cours")>0),"En cours","À faire")) -> À faire
A27: MOB-ZD|0 | B27: Mobile | C27: MOB-ZD | D27: Composants métier et responsive | E27: 0 | F27: =COUNTIFS(Backlog!$K$6:$K$1327,A27) -> 14 | G27: =SUMIFS(Backlog!$I$6:$I$1327,Backlog!$K$6:$K$1327,A27) -> 16.5 | H27: =IF(B27="API",Paramètres!$B$7,IF(B27="Mobile",Paramètres!$B$8,Paramètres!$B$9)) -> 3 | I27: =MAX(1,ROUNDUP(G27*(1+Paramètres!$B$6)/(H27*Paramètres!$B$5),0)) -> 8 | J27: =Paramètres!$B$4 -> 46328 | K27: =ROUNDUP(I27/5,0) -> 2 | L27: =MAX(J27,WORKDAY(M26,1)) -> 46400 | M27: =WORKDAY(L27,I27-1) -> 46409 | N27: =COUNTIFS(Backlog!$K$6:$K$1327,A27,Backlog!$O$6:$O$1327,"Terminé") -> 0 | O27: =IF(F27=0,0,N27/F27) -> 0 | P27: =IF(O27=1,"Terminé",IF(OR(O27>0,COUNTIFS(Backlog!$K$6:$K$1327,A27,Backlog!$O$6:$O$1327,"En cours")>0),"En cours","À faire")) -> À faire
A28: MOB-ZE|0 | B28: Mobile | C28: MOB-ZE | D28: Animations et micro-interactions | E28: 0 | F28: =COUNTIFS(Backlog!$K$6:$K$1327,A28) -> 18 | G28: =SUMIFS(Backlog!$I$6:$I$1327,Backlog!$K$6:$K$1327,A28) -> 19.5 | H28: =IF(B28="API",Paramètres!$B$7,IF(B28="Mobile",Paramètres!$B$8,Paramètres!$B$9)) -> 3 | I28: =MAX(1,ROUNDUP(G28*(1+Paramètres!$B$6)/(H28*Paramètres!$B$5),0)) -> 10 | J28: =Paramètres!$B$4 -> 46328 | K28: =ROUNDUP(I28/5,0) -> 2 | L28: =MAX(J28,WORKDAY(M27,1)) -> 46412 | M28: =WORKDAY(L28,I28-1) -> 46423 | N28: =COUNTIFS(Backlog!$K$6:$K$1327,A28,Backlog!$O$6:$O$1327,"Terminé") -> 0 | O28: =IF(F28=0,0,N28/F28) -> 0 | P28: =IF(O28=1,"Terminé",IF(OR(O28>0,COUNTIFS(Backlog!$K$6:$K$1327,A28,Backlog!$O$6:$O$1327,"En cours")>0),"En cours","À faire")) -> À faire
A29: MOB-A|0 | B29: Mobile | C29: MOB-A | D29: Lancement et système | E29: 0 | F29: =COUNTIFS(Backlog!$K$6:$K$1327,A29) -> 19 | G29: =SUMIFS(Backlog!$I$6:$I$1327,Backlog!$K$6:$K$1327,A29) -> 16 | H29: =IF(B29="API",Paramètres!$B$7,IF(B29="Mobile",Paramètres!$B$8,Paramètres!$B$9)) -> 3 | I29: =MAX(1,ROUNDUP(G29*(1+Paramètres!$B$6)/(H29*Paramètres!$B$5),0)) -> 8 | J29: =Paramètres!$B$4 -> 46328 | K29: =ROUNDUP(I29/5,0) -> 2 | L29: =MAX(J29,WORKDAY(M28,1)) -> 46426 | M29: =WORKDAY(L29,I29-1) -> 46435 | N29: =COUNTIFS(Backlog!$K$6:$K$1327,A29,Backlog!$O$6:$O$1327,"Terminé") -> 0 | O29: =IF(F29=0,0,N29/F29) -> 0 | P29: =IF(O29=1,"Terminé",IF(OR(O29>0,COUNTIFS(Backlog!$K$6:$K$1327,A29,Backlog!$O$6:$O$1327,"En cours")>0),"En cours","À faire")) -> À faire
A30: MOB-B|1 | B30: Mobile | C30: MOB-B | D30: Onboarding et authentification | E30: 1 | F30: =COUNTIFS(Backlog!$K$6:$K$1327,A30) -> 29 | G30: =SUMIFS(Backlog!$I$6:$I$1327,Backlog!$K$6:$K$1327,A30) -> 27.75 | H30: =IF(B30="API",Paramètres!$B$7,IF(B30="Mobile",Paramètres!$B$8,Paramètres!$B$9)) -> 3 | I30: =MAX(1,ROUNDUP(G30*(1+Paramètres!$B$6)/(H30*Paramètres!$B$5),0)) -> 14 | J30: =WORKDAY(_xlfn.MINIFS($L$6:$L$22,$E$6:$E$22,E30),Paramètres!$B$10) -> 46363 | K30: =ROUNDUP(I30/5,0) -> 3 | L30: =MAX(J30,WORKDAY(M29,1)) -> 46436 | M30: =WORKDAY(L30,I30-1) -> 46455 | N30: =COUNTIFS(Backlog!$K$6:$K$1327,A30,Backlog!$O$6:$O$1327,"Terminé") -> 0 | O30: =IF(F30=0,0,N30/F30) -> 0 | P30: =IF(O30=1,"Terminé",IF(OR(O30>0,COUNTIFS(Backlog!$K$6:$K$1327,A30,Backlog!$O$6:$O$1327,"En cours")>0),"En cours","À faire")) -> À faire
A31: MOB-Q|1 | B31: Mobile | C31: MOB-Q | D31: Paramètres et compte | E31: 1 | F31: =COUNTIFS(Backlog!$K$6:$K$1327,A31) -> 31 | G31: =SUMIFS(Backlog!$I$6:$I$1327,Backlog!$K$6:$K$1327,A31) -> 26.5 | H31: =IF(B31="API",Paramètres!$B$7,IF(B31="Mobile",Paramètres!$B$8,Paramètres!$B$9)) -> 3 | I31: =MAX(1,ROUNDUP(G31*(1+Paramètres!$B$6)/(H31*Paramètres!$B$5),0)) -> 13 | J31: =WORKDAY(_xlfn.MINIFS($L$6:$L$22,$E$6:$E$22,E31),Paramètres!$B$10) -> 46363 | K31: =ROUNDUP(I31/5,0) -> 3 | L31: =MAX(J31,WORKDAY(M30,1)) -> 46456 | M31: =WORKDAY(L31,I31-1) -> 46472 | N31: =COUNTIFS(Backlog!$K$6:$K$1327,A31,Backlog!$O$6:$O$1327,"Terminé") -> 0 | O31: =IF(F31=0,0,N31/F31) -> 0 | P31: =IF(O31=1,"Terminé",IF(OR(O31>0,COUNTIFS(Backlog!$K$6:$K$1327,A31,Backlog!$O$6:$O$1327,"En cours")>0),"En cours","À faire")) -> À faire
A32: MOB-C|1 | B32: Mobile | C32: MOB-C | D32: Accueil — dashboard | E32: 1 | F32: =COUNTIFS(Backlog!$K$6:$K$1327,A32) -> 27 | G32: =SUMIFS(Backlog!$I$6:$I$1327,Backlog!$K$6:$K$1327,A32) -> 24.5 | H32: =IF(B32="API",Paramètres!$B$7,IF(B32="Mobile",Paramètres!$B$8,Paramètres!$B$9)) -> 3 | I32: =MAX(1,ROUNDUP(G32*(1+Paramètres!$B$6)/(H32*Paramètres!$B$5),0)) -> 12 | J32: =WORKDAY(_xlfn.MINIFS($L$6:$L$22,$E$6:$E$22,E32),Paramètres!$B$10) -> 46363 | K32: =ROUNDUP(I32/5,0) -> 3 | L32: =MAX(J32,WORKDAY(M31,1)) -> 46475 | M32: =WORKDAY(L32,I32-1) -> 46490 | N32: =COUNTIFS(Backlog!$K$6:$K$1327,A32,Backlog!$O$6:$O$1327,"Terminé") -> 0 | O32: =IF(F32=0,0,N32/F32) -> 0 | P32: =IF(O32=1,"Terminé",IF(OR(O32>0,COUNTIFS(Backlog!$K$6:$K$1327,A32,Backlog!$O$6:$O$1327,"En cours")>0),"En cours","À faire")) -> À faire
A33: MOB-F|1 | B33: Mobile | C33: MOB-F | D33: Historique et fiches | E33: 1 | F33: =COUNTIFS(Backlog!$K$6:$K$1327,A33) -> 27 | G33: =SUMIFS(Backlog!$I$6:$I$1327,Backlog!$K$6:$K$1327,A33) -> 27.5 | H33: =IF(B33="API",Paramètres!$B$7,IF(B33="Mobile",Paramètres!$B$8,Paramètres!$B$9)) -> 3 | I33: =MAX(1,ROUNDUP(G33*(1+Paramètres!$B$6)/(H33*Paramètres!$B$5),0)) -> 14 | J33: =WORKDAY(_xlfn.MINIFS($L$6:$L$22,$E$6:$E$22,E33),Paramètres!$B$10) -> 46363 | K33: =ROUNDUP(I33/5,0) -> 3 | L33: =MAX(J33,WORKDAY(M32,1)) -> 46491 | M33: =WORKDAY(L33,I33-1) -> 46510 | N33: =COUNTIFS(Backlog!$K$6:$K$1327,A33,Backlog!$O$6:$O$1327,"Terminé") -> 0 | O33: =IF(F33=0,0,N33/F33) -> 0 | P33: =IF(O33=1,"Terminé",IF(OR(O33>0,COUNTIFS(Backlog!$K$6:$K$1327,A33,Backlog!$O$6:$O$1327,"En cours")>0),"En cours","À faire")) -> À faire
A34: MOB-L|1 | B34: Mobile | C34: MOB-L | D34: Calendrier et export agenda | E34: 1 | F34: =COUNTIFS(Backlog!$K$6:$K$1327,A34) -> 29 | G34: =SUMIFS(Backlog!$I$6:$I$1327,Backlog!$K$6:$K$1327,A34) -> 34 | H34: =IF(B34="API",Paramètres!$B$7,IF(B34="Mobile",Paramètres!$B$8,Paramètres!$B$9)) -> 3 | I34: =MAX(1,ROUNDUP(G34*(1+Paramètres!$B$6)/(H34*Paramètres!$B$5),0)) -> 17 | J34: =WORKDAY(_xlfn.MINIFS($L$6:$L$22,$E$6:$E$22,E34),Paramètres!$B$10) -> 46363 | K34: =ROUNDUP(I34/5,0) -> 4 | L34: =MAX(J34,WORKDAY(M33,1)) -> 46511 | M34: =WORKDAY(L34,I34-1) -> 46533 | N34: =COUNTIFS(Backlog!$K$6:$K$1327,A34,Backlog!$O$6:$O$1327,"Terminé") -> 0 | O34: =IF(F34=0,0,N34/F34) -> 0 | P34: =IF(O34=1,"Terminé",IF(OR(O34>0,COUNTIFS(Backlog!$K$6:$K$1327,A34,Backlog!$O$6:$O$1327,"En cours")>0),"En cours","À faire")) -> À faire
A35: MOB-D|1 | B35: Mobile | C35: MOB-D | D35: Jeux — Guess the Player | E35: 1 | F35: =COUNTIFS(Backlog!$K$6:$K$1327,A35) -> 30 | G35: =SUMIFS(Backlog!$I$6:$I$1327,Backlog!$K$6:$K$1327,A35) -> 25.75 | H35: =IF(B35="API",Paramètres!$B$7,IF(B35="Mobile",Paramètres!$B$8,Paramètres!$B$9)) -> 3 | I35: =MAX(1,ROUNDUP(G35*(1+Paramètres!$B$6)/(H35*Paramètres!$B$5),0)) -> 13 | J35: =WORKDAY(_xlfn.MINIFS($L$6:$L$22,$E$6:$E$22,E35),Paramètres!$B$10) -> 46363 | K35: =ROUNDUP(I35/5,0) -> 3 | L35: =MAX(J35,WORKDAY(M34,1)) -> 46534 | M35: =WORKDAY(L35,I35-1) -> 46552 | N35: =COUNTIFS(Backlog!$K$6:$K$1327,A35,Backlog!$O$6:$O$1327,"Terminé") -> 0 | O35: =IF(F35=0,0,N35/F35) -> 0 | P35: =IF(O35=1,"Terminé",IF(OR(O35>0,COUNTIFS(Backlog!$K$6:$K$1327,A35,Backlog!$O$6:$O$1327,"En cours")>0),"En cours","À faire")) -> À faire
A36: MOB-E|1 | B36: Mobile | C36: MOB-E | D36: Quiz adaptatif | E36: 1 | F36: =COUNTIFS(Backlog!$K$6:$K$1327,A36) -> 34 | G36: =SUMIFS(Backlog!$I$6:$I$1327,Backlog!$K$6:$K$1327,A36) -> 29.25 | H36: =IF(B36="API",Paramètres!$B$7,IF(B36="Mobile",Paramètres!$B$8,Paramètres!$B$9)) -> 3 | I36: =MAX(1,ROUNDUP(G36*(1+Paramètres!$B$6)/(H36*Paramètres!$B$5),0)) -> 15 | J36: =WORKDAY(_xlfn.MINIFS($L$6:$L$22,$E$6:$E$22,E36),Paramètres!$B$10) -> 46363 | K36: =ROUNDUP(I36/5,0) -> 3 | L36: =MAX(J36,WORKDAY(M35,1)) -> 46553 | M36: =WORKDAY(L36,I36-1) -> 46573 | N36: =COUNTIFS(Backlog!$K$6:$K$1327,A36,Backlog!$O$6:$O$1327,"Terminé") -> 0 | O36: =IF(F36=0,0,N36/F36) -> 0 | P36: =IF(O36=1,"Terminé",IF(OR(O36>0,COUNTIFS(Backlog!$K$6:$K$1327,A36,Backlog!$O$6:$O$1327,"En cours")>0),"En cours","À faire")) -> À faire
A37: MOB-N|1 | B37: Mobile | C37: MOB-N | D37: Assistant IA Barça AI | E37: 1 | F37: =COUNTIFS(Backlog!$K$6:$K$1327,A37) -> 31 | G37: =SUMIFS(Backlog!$I$6:$I$1327,Backlog!$K$6:$K$1327,A37) -> 35.5 | H37: =IF(B37="API",Paramètres!$B$7,IF(B37="Mobile",Paramètres!$B$8,Paramètres!$B$9)) -> 3 | I37: =MAX(1,ROUNDUP(G37*(1+Paramètres!$B$6)/(H37*Paramètres!$B$5),0)) -> 18 | J37: =WORKDAY(_xlfn.MINIFS($L$6:$L$22,$E$6:$E$22,E37),Paramètres!$B$10) -> 46363 | K37: =ROUNDUP(I37/5,0) -> 4 | L37: =MAX(J37,WORKDAY(M36,1)) -> 46574 | M37: =WORKDAY(L37,I37-1) -> 46597 | N37: =COUNTIFS(Backlog!$K$6:$K$1327,A37,Backlog!$O$6:$O$1327,"Terminé") -> 0 | O37: =IF(F37=0,0,N37/F37) -> 0 | P37: =IF(O37=1,"Terminé",IF(OR(O37>0,COUNTIFS(Backlog!$K$6:$K$1327,A37,Backlog!$O$6:$O$1327,"En cours")>0),"En cours","À faire")) -> À faire
A38: MOB-O|1 | B38: Mobile | C38: MOB-O | D38: Notifications | E38: 1 | F38: =COUNTIFS(Backlog!$K$6:$K$1327,A38) -> 28 | G38: =SUMIFS(Backlog!$I$6:$I$1327,Backlog!$K$6:$K$1327,A38) -> 24.75 | H38: =IF(B38="API",Paramètres!$B$7,IF(B38="Mobile",Paramètres!$B$8,Paramètres!$B$9)) -> 3 | I38: =MAX(1,ROUNDUP(G38*(1+Paramètres!$B$6)/(H38*Paramètres!$B$5),0)) -> 12 | J38: =WORKDAY(_xlfn.MINIFS($L$6:$L$22,$E$6:$E$22,E38),Paramètres!$B$10) -> 46363 | K38: =ROUNDUP(I38/5,0) -> 3 | L38: =MAX(J38,WORKDAY(M37,1)) -> 46598 | M38: =WORKDAY(L38,I38-1) -> 46615 | N38: =COUNTIFS(Backlog!$K$6:$K$1327,A38,Backlog!$O$6:$O$1327,"Terminé") -> 0 | O38: =IF(F38=0,0,N38/F38) -> 0 | P38: =IF(O38=1,"Terminé",IF(OR(O38>0,COUNTIFS(Backlog!$K$6:$K$1327,A38,Backlog!$O$6:$O$1327,"En cours")>0),"En cours","À faire")) -> À faire
A39: MOB-G|2 | B39: Mobile | C39: MOB-G | D39: Comparateur GOAT | E39: 2 | F39: =COUNTIFS(Backlog!$K$6:$K$1327,A39) -> 17 | G39: =SUMIFS(Backlog!$I$6:$I$1327,Backlog!$K$6:$K$1327,A39) -> 18 | H39: =IF(B39="API",Paramètres!$B$7,IF(B39="Mobile",Paramètres!$B$8,Paramètres!$B$9)) -> 3 | I39: =MAX(1,ROUNDUP(G39*(1+Paramètres!$B$6)/(H39*Paramètres!$B$5),0)) -> 9 | J39: =WORKDAY(_xlfn.MINIFS($L$6:$L$22,$E$6:$E$22,E39),Paramètres!$B$10) -> 46555 | K39: =ROUNDUP(I39/5,0) -> 2 | L39: =MAX(J39,WORKDAY(M38,1)) -> 46616 | M39: =WORKDAY(L39,I39-1) -> 46626 | N39: =COUNTIFS(Backlog!$K$6:$K$1327,A39,Backlog!$O$6:$O$1327,"Terminé") -> 0 | O39: =IF(F39=0,0,N39/F39) -> 0 | P39: =IF(O39=1,"Terminé",IF(OR(O39>0,COUNTIFS(Backlog!$K$6:$K$1327,A39,Backlog!$O$6:$O$1327,"En cours")>0),"En cours","À faire")) -> À faire
A40: MOB-H|2 | B40: Mobile | C40: MOB-H | D40: Fantasy Barça | E40: 2 | F40: =COUNTIFS(Backlog!$K$6:$K$1327,A40) -> 35 | G40: =SUMIFS(Backlog!$I$6:$I$1327,Backlog!$K$6:$K$1327,A40) -> 38 | H40: =IF(B40="API",Paramètres!$B$7,IF(B40="Mobile",Paramètres!$B$8,Paramètres!$B$9)) -> 3 | I40: =MAX(1,ROUNDUP(G40*(1+Paramètres!$B$6)/(H40*Paramètres!$B$5),0)) -> 19 | J40: =WORKDAY(_xlfn.MINIFS($L$6:$L$22,$E$6:$E$22,E40),Paramètres!$B$10) -> 46555 | K40: =ROUNDUP(I40/5,0) -> 4 | L40: =MAX(J40,WORKDAY(M39,1)) -> 46629 | M40: =WORKDAY(L40,I40-1) -> 46653 | N40: =COUNTIFS(Backlog!$K$6:$K$1327,A40,Backlog!$O$6:$O$1327,"Terminé") -> 0 | O40: =IF(F40=0,0,N40/F40) -> 0 | P40: =IF(O40=1,"Terminé",IF(OR(O40>0,COUNTIFS(Backlog!$K$6:$K$1327,A40,Backlog!$O$6:$O$1327,"En cours")>0),"En cours","À faire")) -> À faire
A41: MOB-J|2 | B41: Mobile | C41: MOB-J | D41: Carte communautaire | E41: 2 | F41: =COUNTIFS(Backlog!$K$6:$K$1327,A41) -> 27 | G41: =SUMIFS(Backlog!$I$6:$I$1327,Backlog!$K$6:$K$1327,A41) -> 27.5 | H41: =IF(B41="API",Paramètres!$B$7,IF(B41="Mobile",Paramètres!$B$8,Paramètres!$B$9)) -> 3 | I41: =MAX(1,ROUNDUP(G41*(1+Paramètres!$B$6)/(H41*Paramètres!$B$5),0)) -> 14 | J41: =WORKDAY(_xlfn.MINIFS($L$6:$L$22,$E$6:$E$22,E41),Paramètres!$B$10) -> 46555 | K41: =ROUNDUP(I41/5,0) -> 3 | L41: =MAX(J41,WORKDAY(M40,1)) -> 46654 | M41: =WORKDAY(L41,I41-1) -> 46673 | N41: =COUNTIFS(Backlog!$K$6:$K$1327,A41,Backlog!$O$6:$O$1327,"Terminé") -> 0 | O41: =IF(F41=0,0,N41/F41) -> 0 | P41: =IF(O41=1,"Terminé",IF(OR(O41>0,COUNTIFS(Backlog!$K$6:$K$1327,A41,Backlog!$O$6:$O$1327,"En cours")>0),"En cours","À faire")) -> À faire
